<?xml version="1.0"?>
<robot name="my_robot">
    <material name="grey">
        <color rgba="0 0 0 1"/>    
    </material>

    <material name="white">
        <color rgba="1 1 1 1" />
    </material>

    <link name="base_footprint"/>

    <link name="base_link">
        <visual>
            <geometry>
                <mesh filename="package://robot_definition/meshes/bodyF.stl" scale="1 1 1"/>
            </geometry>
            <origin xyz="0 0 0" rpy="0 0 0" />
            <material name="grey" />
        </visual>
        <collision>
            <geometry>
                <mesh filename="package://robot_definition/meshes/bodyF.stl" scale="1 1 1"/>
            </geometry>
        </collision>
        <inertial>
            <mass value="1.139"/>
            <inertia ixx="1.18074e-6" 
                 ixy="1.1e-10" 
                 ixz="2.15e-9"
                 iyy="7.3334e-7" 
                 iyz="-9.61e-9"
                 izz="1.339e-6"/>
        </inertial>
    </link>

    <link name="left_wheel">
        <visual>
            <geometry>
                <mesh filename="package://robot_definition/meshes/leftwheelE.stl" scale="1 1 1"/>
            </geometry>
            <origin xyz="0 0 0" rpy="0 0 0" />
            <material name="grey" />
        </visual>
        <collision>
            <geometry>
                <mesh filename="package://robot_definition/meshes/leftwheelE.stl" scale="1 1 1"/>
            </geometry>
        </collision>
        <inertial>
            <mass value="0.029"/>
            <inertia ixx="2.510e-6" 
                ixy="-1e-10" 
                ixz="0"
                iyy="1.34e-6" 
                iyz="0"
                izz="1.341e-6"/>
        </inertial>
    </link>

    <link name="right_wheel">
        <visual>
            <geometry>
                <mesh filename="package://robot_definition/meshes/rightwheelE.stl" scale="1 1 1"/>
            </geometry>
            <origin xyz="0 0 0" rpy="0 0 0" />
            <material name="grey" />
        </visual>
        <collision>
            <geometry>
                <mesh filename="package://robot_definition/meshes/rightwheelE.stl" scale="1 1 1"/>
            </geometry>
        </collision>
        <inertial>
            <mass value="0.029"/>
            <inertia ixx="2.510e-6"
                ixy="1e-10" 
                ixz="0"
                iyy="1.34e-6" 
                iyz="0"
                izz="1.341e-6"/>
        </inertial>
    </link>

    <link name="end_effector">
        <visual>
            <geometry>
                <mesh filename="package://robot_definition/meshes/end_effector_wp.stl" scale="1 1 1"/>
            </geometry>
            <origin xyz="0 0 0" rpy="0 0 0" />
            <material name="grey" />
        </visual>
        <collision>
            <geometry>
                <mesh filename="package://robot_definition/meshes/end_effector_wp.stl" scale="1 1 1"/>
            </geometry>
        </collision>
        <inertial>
            <mass value="0.028"/>
            <inertia ixx="2.510e-6" 
                     ixy="-1e-10" 
                     ixz="0"
                     iyy="1.34e-6" 
                     iyz="0"
                     izz="1.341e-6"/>
        </inertial>
    </link>

      <link name="caster_wheel_front">
    <visual>
        <geometry>
            <sphere radius="0.006"/> 
        </geometry>
        <origin xyz="0 0 0" rpy="0 0 0" />
        <material name="grey" />
    </visual>
    <collision>
        <geometry>
            <sphere radius="0.006"/> 
        </geometry>
    </collision>
    <inertial>
        <mass value="0.00086"/>
        <inertia ixx="3.42525e-12" 
                 ixy="-1.1574e-15" 
                 ixz="2.5714e-16"
                 iyy="3.42478e-12" 
                 iyz="0"
                 izz="6.2555e-12"/>
    </inertial>
</link>

<link name="caster_wheel_back">
    <visual>
        <geometry>
            <sphere radius="0.006"/> 
        </geometry>
        <origin xyz="0 0 0" rpy="0 0 0" />
        <material name="grey" />
    </visual>
    <collision>
        <geometry>
            <sphere radius="0.006"/> 
        </geometry>
    </collision>
    <inertial>
        <mass value="0.00086"/>
        <inertia ixx="3.42525e-12" 
                 ixy="-1.1574e-15" 
                 ixz="2.5714e-16"
                 iyy="3.42478e-12" 
                 iyz="0"
                 izz="6.2555e-12"/>
    </inertial>
</link>

    <joint name="base_joint" type="fixed">
        <parent link="base_footprint" />
        <child link="base_link" />
        <origin xyz="0 0 0" rpy="0 0 0" />
    </joint>

    <joint name="base_left_wheel_joint" type="continuous">
        <parent link="base_link" />
        <child link="left_wheel" />
        <origin xyz="0.0648 -0.000776 -0.013125" rpy="0 0 0" />
        <axis xyz="-1 0 0" />
    </joint>

    <joint name="base_right_wheel_joint" type="continuous">
        <parent link="base_link" />
        <child link="right_wheel" />
        <origin xyz="-0.0648 -0.000776 -0.013125" rpy="0 0 0" />
        <axis xyz="-1 0 0" />
    </joint>

    <joint name="end_effector_joint" type="revolute">
        <parent link="base_link" />
        <child link="end_effector" />
        <origin xyz="0.000056 0.09004 -0.014117" rpy="0 0 0" />
        <axis xyz="1 0 0" />
        <limit lower="0" upper="1.57" effort="0" velocity="0" />
    </joint>

     <joint name="front_caster_joint" type="continuous">
        <parent link="base_link" />
        <child link="caster_wheel_front" />
        <origin xyz="0 0.044373 -0.040125" rpy="0 0 0" />
        <axis xyz="-1 0 0" />
    </joint>

    <joint name="back_caster_joint" type="continuous">
        <parent link="base_link" />
        <child link="caster_wheel_back" />
        <origin xyz="0 -0.051640 -0.040125" rpy="0 0 0" />
        <axis xyz="-1 0 0" />
    </joint>
</robot>
